Traceback (most recent call last):
  File "C:\Users\grand\AppData\Local\Programs\Python\Python39\lib\site-packages\scapy\fields.py", line 861, in h2i
    inet_aton(x)
OSError: illegal IP address string passed to inet_aton

During handling of the above exception, another exception occurred:

Traceback (most recent call last):
  File "D:\Developer\GFW-Research\src\scripts\GFW_Location_IPBlocking.py", line 212, in <module>
    results = process_domains_concurrently(domains)
  File "D:\Developer\GFW-Research\src\scripts\GFW_Location_IPBlocking.py", line 178, in process_domains_concurrently
    results.append(future.result())
  File "C:\Users\grand\AppData\Local\Programs\Python\Python39\lib\concurrent\futures\_base.py", line 433, in result
    return self.__get_result()
  File "C:\Users\grand\AppData\Local\Programs\Python\Python39\lib\concurrent\futures\_base.py", line 389, in __get_result
    raise self._exception
  File "C:\Users\grand\AppData\Local\Programs\Python\Python39\lib\concurrent\futures\thread.py", line 52, in run
    result = self.fn(*self.args, **self.kwargs)
  File "D:\Developer\GFW-Research\src\scripts\GFW_Location_IPBlocking.py", line 143, in process_domain
    traceroute_output = traceroute(domain, use_ipv6=False)
  File "D:\Developer\GFW-Research\src\scripts\GFW_Location_IPBlocking.py", line 76, in traceroute
    pkt = IP(dst=ip) / TCP(dport=80, flags="S")
  File "C:\Users\grand\AppData\Local\Programs\Python\Python39\lib\site-packages\scapy\base_classes.py", line 481, in __call__
    i.__init__(*args, **kargs)
  File "C:\Users\grand\AppData\Local\Programs\Python\Python39\lib\site-packages\scapy\packet.py", line 199, in __init__
    self.get_field(fname).any2i(self, value)
  File "C:\Users\grand\AppData\Local\Programs\Python\Python39\lib\site-packages\scapy\fields.py", line 900, in any2i
    return self.h2i(pkt, x)
  File "C:\Users\grand\AppData\Local\Programs\Python\Python39\lib\site-packages\scapy\fields.py", line 863, in h2i
    return Net(x)
  File "C:\Users\grand\AppData\Local\Programs\Python\Python39\lib\site-packages\scapy\base_classes.py", line 232, in __init__
    self.start = self.ip2int(net) >> inv_mask << inv_mask
  File "C:\Users\grand\AppData\Local\Programs\Python\Python39\lib\site-packages\scapy\base_classes.py", line 205, in ip2int
    "!I", socket.inet_aton(cls.name2addr(addr))
  File "C:\Users\grand\AppData\Local\Programs\Python\Python39\lib\site-packages\scapy\base_classes.py", line 192, in name2addr
    socket.getaddrinfo(name, None, cls.family)
  File "C:\Users\grand\AppData\Local\Programs\Python\Python39\lib\socket.py", line 953, in getaddrinfo
    for res in _socket.getaddrinfo(host, port, family, type, proto, flags):
socket.gaierror: [Errno 11001] getaddrinfo failed
